2023-12-20 18:38:07,911 ERROR frappe New Exception collected with id: 2023-12-20 18:38:07.590165-127.0.0.1-0a4
Site: site2.local
Form Dict: {}
2023-12-20 18:38:07,935 ERROR frappe Failed to run after request hook
Site: site2.local
Form Dict: {}
Traceback (most recent call last):
  File "/home/ubuntu/frappe-bench/apps/frappe/frappe/app.py", line 84, in application
    init_request(request)
  File "/home/ubuntu/frappe-bench/apps/frappe/frappe/app.py", line 175, in init_request
    frappe.local.http_request = frappe.auth.HTTPRequest()
  File "/home/ubuntu/frappe-bench/apps/frappe/frappe/auth.py", line 37, in __init__
    self.set_session()
  File "/home/ubuntu/frappe-bench/apps/frappe/frappe/auth.py", line 73, in set_session
    frappe.local.login_manager = LoginManager()
  File "/home/ubuntu/frappe-bench/apps/frappe/frappe/auth.py", line 122, in __init__
    self.make_session(resume=True)
  File "/home/ubuntu/frappe-bench/apps/frappe/frappe/auth.py", line 210, in make_session
    frappe.local.session_obj = Session(
  File "/home/ubuntu/frappe-bench/apps/frappe/frappe/sessions.py", line 230, in __init__
    self.resume()
  File "/home/ubuntu/frappe-bench/apps/frappe/frappe/sessions.py", line 303, in resume
    data = self.get_session_record()
  File "/home/ubuntu/frappe-bench/apps/frappe/frappe/sessions.py", line 321, in get_session_record
    r = self.get_session_data()
  File "/home/ubuntu/frappe-bench/apps/frappe/frappe/sessions.py", line 337, in get_session_data
    data = self.get_session_data_from_db()
  File "/home/ubuntu/frappe-bench/apps/frappe/frappe/sessions.py", line 362, in get_session_data_from_db
    frappe.db.get_value(
  File "/home/ubuntu/frappe-bench/apps/frappe/frappe/database/database.py", line 509, in get_value
    result = self.get_values(
  File "/home/ubuntu/frappe-bench/apps/frappe/frappe/database/database.py", line 606, in get_values
    out = self._get_values_from_table(
  File "/home/ubuntu/frappe-bench/apps/frappe/frappe/database/database.py", line 835, in _get_values_from_table
    return query.run(as_dict=as_dict, debug=debug, update=update, run=run, pluck=pluck)
  File "/home/ubuntu/frappe-bench/apps/frappe/frappe/query_builder/utils.py", line 87, in execute_query
    result = frappe.db.sql(query, params, *args, **kwargs)  # nosemgrep
  File "/home/ubuntu/frappe-bench/apps/frappe/frappe/database/database.py", line 201, in sql
    self.connect()
  File "/home/ubuntu/frappe-bench/apps/frappe/frappe/database/database.py", line 115, in connect
    self._conn = self.get_connection()
  File "/home/ubuntu/frappe-bench/apps/frappe/frappe/database/mariadb/database.py", line 98, in get_connection
    conn = self._get_connection()
  File "/home/ubuntu/frappe-bench/apps/frappe/frappe/database/mariadb/database.py", line 104, in _get_connection
    return self.create_connection()
  File "/home/ubuntu/frappe-bench/apps/frappe/frappe/database/mariadb/database.py", line 107, in create_connection
    return pymysql.connect(**self.get_connection_settings())
  File "/home/ubuntu/frappe-bench/env/lib/python3.10/site-packages/pymysql/connections.py", line 352, in __init__
    self.connect()
  File "/home/ubuntu/frappe-bench/env/lib/python3.10/site-packages/pymysql/connections.py", line 636, in connect
    self._request_authentication()
  File "/home/ubuntu/frappe-bench/env/lib/python3.10/site-packages/pymysql/connections.py", line 911, in _request_authentication
    auth_packet = self._read_packet()
  File "/home/ubuntu/frappe-bench/env/lib/python3.10/site-packages/pymysql/connections.py", line 729, in _read_packet
    packet.raise_for_error()
  File "/home/ubuntu/frappe-bench/env/lib/python3.10/site-packages/pymysql/protocol.py", line 221, in raise_for_error
    err.raise_mysql_exception(self._data)
  File "/home/ubuntu/frappe-bench/env/lib/python3.10/site-packages/pymysql/err.py", line 143, in raise_mysql_exception
    raise errorclass(errno, errval)
pymysql.err.OperationalError: (1045, "Access denied for user '_c91b619255899dde'@'localhost' (using password: YES)")

During handling of the above exception, another exception occurred:

Traceback (most recent call last):
  File "/home/ubuntu/frappe-bench/apps/frappe/frappe/utils/caching.py", line 55, in wrapper
    return frappe.local.request_cache[func][args_key]
KeyError: 5740354900026072187

During handling of the above exception, another exception occurred:

Traceback (most recent call last):
  File "/home/ubuntu/frappe-bench/apps/frappe/frappe/utils/caching.py", line 55, in wrapper
    return frappe.local.request_cache[func][args_key]
KeyError: -7777928797930344328

During handling of the above exception, another exception occurred:

Traceback (most recent call last):
  File "/home/ubuntu/frappe-bench/apps/frappe/frappe/website/serve.py", line 17, in get_response
    endpoint, renderer_instance = path_resolver.resolve()
  File "/home/ubuntu/frappe-bench/apps/frappe/frappe/website/path_resolver.py", line 36, in resolve
    resolve_redirect(self.path, request.query_string)
  File "/home/ubuntu/frappe-bench/apps/frappe/frappe/website/path_resolver.py", line 107, in resolve_redirect
    redirects = frappe.get_hooks("website_redirects")
  File "/home/ubuntu/frappe-bench/apps/frappe/frappe/__init__.py", line 1519, in get_hooks
    hooks = _dict(cache().get_value("app_hooks", _load_app_hooks))
  File "/home/ubuntu/frappe-bench/apps/frappe/frappe/utils/redis_wrapper.py", line 81, in get_value
    val = generator()
  File "/home/ubuntu/frappe-bench/apps/frappe/frappe/utils/caching.py", line 57, in wrapper
    return_val = func(*args, **kwargs)
  File "/home/ubuntu/frappe-bench/apps/frappe/frappe/__init__.py", line 1482, in _load_app_hooks
    apps = [app_name] if app_name else get_installed_apps(_ensure_on_bench=True)
  File "/home/ubuntu/frappe-bench/apps/frappe/frappe/utils/caching.py", line 57, in wrapper
    return_val = func(*args, **kwargs)
  File "/home/ubuntu/frappe-bench/apps/frappe/frappe/__init__.py", line 1438, in get_installed_apps
    installed = json.loads(db.get_global("installed_apps") or "[]")
  File "/home/ubuntu/frappe-bench/apps/frappe/frappe/database/database.py", line 975, in get_global
    return self.get_default(key, user)
  File "/home/ubuntu/frappe-bench/apps/frappe/frappe/database/database.py", line 979, in get_default
    d = self.get_defaults(key, parent)
  File "/home/ubuntu/frappe-bench/apps/frappe/frappe/database/database.py", line 995, in get_defaults
    defaults = frappe.defaults.get_defaults_for(parent)
  File "/home/ubuntu/frappe-bench/apps/frappe/frappe/defaults.py", line 238, in get_defaults_for
    frappe.qb.from_(table)
  File "/home/ubuntu/frappe-bench/apps/frappe/frappe/query_builder/utils.py", line 87, in execute_query
    result = frappe.db.sql(query, params, *args, **kwargs)  # nosemgrep
  File "/home/ubuntu/frappe-bench/apps/frappe/frappe/database/database.py", line 201, in sql
    self.connect()
  File "/home/ubuntu/frappe-bench/apps/frappe/frappe/database/database.py", line 115, in connect
    self._conn = self.get_connection()
  File "/home/ubuntu/frappe-bench/apps/frappe/frappe/database/mariadb/database.py", line 98, in get_connection
    conn = self._get_connection()
  File "/home/ubuntu/frappe-bench/apps/frappe/frappe/database/mariadb/database.py", line 104, in _get_connection
    return self.create_connection()
  File "/home/ubuntu/frappe-bench/apps/frappe/frappe/database/mariadb/database.py", line 107, in create_connection
    return pymysql.connect(**self.get_connection_settings())
  File "/home/ubuntu/frappe-bench/env/lib/python3.10/site-packages/pymysql/connections.py", line 352, in __init__
    self.connect()
  File "/home/ubuntu/frappe-bench/env/lib/python3.10/site-packages/pymysql/connections.py", line 636, in connect
    self._request_authentication()
  File "/home/ubuntu/frappe-bench/env/lib/python3.10/site-packages/pymysql/connections.py", line 911, in _request_authentication
    auth_packet = self._read_packet()
  File "/home/ubuntu/frappe-bench/env/lib/python3.10/site-packages/pymysql/connections.py", line 729, in _read_packet
    packet.raise_for_error()
  File "/home/ubuntu/frappe-bench/env/lib/python3.10/site-packages/pymysql/protocol.py", line 221, in raise_for_error
    err.raise_mysql_exception(self._data)
  File "/home/ubuntu/frappe-bench/env/lib/python3.10/site-packages/pymysql/err.py", line 143, in raise_mysql_exception
    raise errorclass(errno, errval)
pymysql.err.OperationalError: (1045, "Access denied for user '_c91b619255899dde'@'localhost' (using password: YES)")

During handling of the above exception, another exception occurred:

Traceback (most recent call last):
  File "/home/ubuntu/frappe-bench/apps/frappe/frappe/utils/caching.py", line 55, in wrapper
    return frappe.local.request_cache[func][args_key]
KeyError: -7246609608310958455

During handling of the above exception, another exception occurred:

Traceback (most recent call last):
  File "/home/ubuntu/frappe-bench/apps/frappe/frappe/app.py", line 113, in application
    response = handle_exception(e)
  File "/home/ubuntu/frappe-bench/apps/frappe/frappe/app.py", line 369, in handle_exception
    response = get_response("message", http_status_code=http_status_code)
  File "/home/ubuntu/frappe-bench/apps/frappe/frappe/website/serve.py", line 26, in get_response
    response = ErrorPage(exception=e).render()
  File "/home/ubuntu/frappe-bench/apps/frappe/frappe/website/page_renderers/error_page.py", line 7, in __init__
    super().__init__(path=path, http_status_code=http_status_code)
  File "/home/ubuntu/frappe-bench/apps/frappe/frappe/website/page_renderers/template_page.py", line 45, in __init__
    self.set_template_path()
  File "/home/ubuntu/frappe-bench/apps/frappe/frappe/website/page_renderers/template_page.py", line 53, in set_template_path
    for app in frappe.get_installed_apps(frappe_last=True):
  File "/home/ubuntu/frappe-bench/apps/frappe/frappe/utils/caching.py", line 57, in wrapper
    return_val = func(*args, **kwargs)
  File "/home/ubuntu/frappe-bench/apps/frappe/frappe/__init__.py", line 1438, in get_installed_apps
    installed = json.loads(db.get_global("installed_apps") or "[]")
  File "/home/ubuntu/frappe-bench/apps/frappe/frappe/database/database.py", line 975, in get_global
    return self.get_default(key, user)
  File "/home/ubuntu/frappe-bench/apps/frappe/frappe/database/database.py", line 979, in get_default
    d = self.get_defaults(key, parent)
  File "/home/ubuntu/frappe-bench/apps/frappe/frappe/database/database.py", line 995, in get_defaults
    defaults = frappe.defaults.get_defaults_for(parent)
  File "/home/ubuntu/frappe-bench/apps/frappe/frappe/defaults.py", line 238, in get_defaults_for
    frappe.qb.from_(table)
  File "/home/ubuntu/frappe-bench/apps/frappe/frappe/query_builder/utils.py", line 87, in execute_query
    result = frappe.db.sql(query, params, *args, **kwargs)  # nosemgrep
  File "/home/ubuntu/frappe-bench/apps/frappe/frappe/database/database.py", line 201, in sql
    self.connect()
  File "/home/ubuntu/frappe-bench/apps/frappe/frappe/database/database.py", line 115, in connect
    self._conn = self.get_connection()
  File "/home/ubuntu/frappe-bench/apps/frappe/frappe/database/mariadb/database.py", line 98, in get_connection
    conn = self._get_connection()
  File "/home/ubuntu/frappe-bench/apps/frappe/frappe/database/mariadb/database.py", line 104, in _get_connection
    return self.create_connection()
  File "/home/ubuntu/frappe-bench/apps/frappe/frappe/database/mariadb/database.py", line 107, in create_connection
    return pymysql.connect(**self.get_connection_settings())
  File "/home/ubuntu/frappe-bench/env/lib/python3.10/site-packages/pymysql/connections.py", line 352, in __init__
    self.connect()
  File "/home/ubuntu/frappe-bench/env/lib/python3.10/site-packages/pymysql/connections.py", line 636, in connect
    self._request_authentication()
  File "/home/ubuntu/frappe-bench/env/lib/python3.10/site-packages/pymysql/connections.py", line 911, in _request_authentication
    auth_packet = self._read_packet()
  File "/home/ubuntu/frappe-bench/env/lib/python3.10/site-packages/pymysql/connections.py", line 729, in _read_packet
    packet.raise_for_error()
  File "/home/ubuntu/frappe-bench/env/lib/python3.10/site-packages/pymysql/protocol.py", line 221, in raise_for_error
    err.raise_mysql_exception(self._data)
  File "/home/ubuntu/frappe-bench/env/lib/python3.10/site-packages/pymysql/err.py", line 143, in raise_mysql_exception
    raise errorclass(errno, errval)
pymysql.err.OperationalError: (1045, "Access denied for user '_c91b619255899dde'@'localhost' (using password: YES)")

During handling of the above exception, another exception occurred:

Traceback (most recent call last):
  File "/home/ubuntu/frappe-bench/apps/frappe/frappe/utils/caching.py", line 55, in wrapper
    return frappe.local.request_cache[func][args_key]
KeyError: 5740354900026072187

During handling of the above exception, another exception occurred:

Traceback (most recent call last):
  File "/home/ubuntu/frappe-bench/apps/frappe/frappe/utils/caching.py", line 55, in wrapper
    return frappe.local.request_cache[func][args_key]
KeyError: -7777928797930344328

During handling of the above exception, another exception occurred:

Traceback (most recent call last):
  File "/home/ubuntu/frappe-bench/apps/frappe/frappe/app.py", line 127, in application
    run_after_request_hooks(request, response)
  File "/home/ubuntu/frappe-bench/apps/frappe/frappe/app.py", line 143, in run_after_request_hooks
    for after_request_task in frappe.get_hooks("after_request"):
  File "/home/ubuntu/frappe-bench/apps/frappe/frappe/__init__.py", line 1519, in get_hooks
    hooks = _dict(cache().get_value("app_hooks", _load_app_hooks))
  File "/home/ubuntu/frappe-bench/apps/frappe/frappe/utils/redis_wrapper.py", line 81, in get_value
    val = generator()
  File "/home/ubuntu/frappe-bench/apps/frappe/frappe/utils/caching.py", line 57, in wrapper
    return_val = func(*args, **kwargs)
  File "/home/ubuntu/frappe-bench/apps/frappe/frappe/__init__.py", line 1482, in _load_app_hooks
    apps = [app_name] if app_name else get_installed_apps(_ensure_on_bench=True)
  File "/home/ubuntu/frappe-bench/apps/frappe/frappe/utils/caching.py", line 57, in wrapper
    return_val = func(*args, **kwargs)
  File "/home/ubuntu/frappe-bench/apps/frappe/frappe/__init__.py", line 1438, in get_installed_apps
    installed = json.loads(db.get_global("installed_apps") or "[]")
  File "/home/ubuntu/frappe-bench/apps/frappe/frappe/database/database.py", line 975, in get_global
    return self.get_default(key, user)
  File "/home/ubuntu/frappe-bench/apps/frappe/frappe/database/database.py", line 979, in get_default
    d = self.get_defaults(key, parent)
  File "/home/ubuntu/frappe-bench/apps/frappe/frappe/database/database.py", line 995, in get_defaults
    defaults = frappe.defaults.get_defaults_for(parent)
  File "/home/ubuntu/frappe-bench/apps/frappe/frappe/defaults.py", line 238, in get_defaults_for
    frappe.qb.from_(table)
  File "/home/ubuntu/frappe-bench/apps/frappe/frappe/query_builder/utils.py", line 87, in execute_query
    result = frappe.db.sql(query, params, *args, **kwargs)  # nosemgrep
  File "/home/ubuntu/frappe-bench/apps/frappe/frappe/database/database.py", line 201, in sql
    self.connect()
  File "/home/ubuntu/frappe-bench/apps/frappe/frappe/database/database.py", line 115, in connect
    self._conn = self.get_connection()
  File "/home/ubuntu/frappe-bench/apps/frappe/frappe/database/mariadb/database.py", line 98, in get_connection
    conn = self._get_connection()
  File "/home/ubuntu/frappe-bench/apps/frappe/frappe/database/mariadb/database.py", line 104, in _get_connection
    return self.create_connection()
  File "/home/ubuntu/frappe-bench/apps/frappe/frappe/database/mariadb/database.py", line 107, in create_connection
    return pymysql.connect(**self.get_connection_settings())
  File "/home/ubuntu/frappe-bench/env/lib/python3.10/site-packages/pymysql/connections.py", line 352, in __init__
    self.connect()
  File "/home/ubuntu/frappe-bench/env/lib/python3.10/site-packages/pymysql/connections.py", line 636, in connect
    self._request_authentication()
  File "/home/ubuntu/frappe-bench/env/lib/python3.10/site-packages/pymysql/connections.py", line 911, in _request_authentication
    auth_packet = self._read_packet()
  File "/home/ubuntu/frappe-bench/env/lib/python3.10/site-packages/pymysql/connections.py", line 729, in _read_packet
    packet.raise_for_error()
  File "/home/ubuntu/frappe-bench/env/lib/python3.10/site-packages/pymysql/protocol.py", line 221, in raise_for_error
    err.raise_mysql_exception(self._data)
  File "/home/ubuntu/frappe-bench/env/lib/python3.10/site-packages/pymysql/err.py", line 143, in raise_mysql_exception
    raise errorclass(errno, errval)
pymysql.err.OperationalError: (1045, "Access denied for user '_c91b619255899dde'@'localhost' (using password: YES)")
2023-12-20 18:39:54,313 ERROR frappe New Exception collected with id: 2023-12-20 18:39:53.978957-127.0.0.1-5a6
Site: site2.local
Form Dict: {}
2023-12-20 18:39:54,351 ERROR frappe Failed to run after request hook
Site: site2.local
Form Dict: {}
Traceback (most recent call last):
  File "/home/ubuntu/frappe-bench/apps/frappe/frappe/app.py", line 84, in application
    init_request(request)
  File "/home/ubuntu/frappe-bench/apps/frappe/frappe/app.py", line 175, in init_request
    frappe.local.http_request = frappe.auth.HTTPRequest()
  File "/home/ubuntu/frappe-bench/apps/frappe/frappe/auth.py", line 37, in __init__
    self.set_session()
  File "/home/ubuntu/frappe-bench/apps/frappe/frappe/auth.py", line 73, in set_session
    frappe.local.login_manager = LoginManager()
  File "/home/ubuntu/frappe-bench/apps/frappe/frappe/auth.py", line 122, in __init__
    self.make_session(resume=True)
  File "/home/ubuntu/frappe-bench/apps/frappe/frappe/auth.py", line 210, in make_session
    frappe.local.session_obj = Session(
  File "/home/ubuntu/frappe-bench/apps/frappe/frappe/sessions.py", line 230, in __init__
    self.resume()
  File "/home/ubuntu/frappe-bench/apps/frappe/frappe/sessions.py", line 303, in resume
    data = self.get_session_record()
  File "/home/ubuntu/frappe-bench/apps/frappe/frappe/sessions.py", line 321, in get_session_record
    r = self.get_session_data()
  File "/home/ubuntu/frappe-bench/apps/frappe/frappe/sessions.py", line 337, in get_session_data
    data = self.get_session_data_from_db()
  File "/home/ubuntu/frappe-bench/apps/frappe/frappe/sessions.py", line 362, in get_session_data_from_db
    frappe.db.get_value(
  File "/home/ubuntu/frappe-bench/apps/frappe/frappe/database/database.py", line 509, in get_value
    result = self.get_values(
  File "/home/ubuntu/frappe-bench/apps/frappe/frappe/database/database.py", line 606, in get_values
    out = self._get_values_from_table(
  File "/home/ubuntu/frappe-bench/apps/frappe/frappe/database/database.py", line 835, in _get_values_from_table
    return query.run(as_dict=as_dict, debug=debug, update=update, run=run, pluck=pluck)
  File "/home/ubuntu/frappe-bench/apps/frappe/frappe/query_builder/utils.py", line 87, in execute_query
    result = frappe.db.sql(query, params, *args, **kwargs)  # nosemgrep
  File "/home/ubuntu/frappe-bench/apps/frappe/frappe/database/database.py", line 201, in sql
    self.connect()
  File "/home/ubuntu/frappe-bench/apps/frappe/frappe/database/database.py", line 115, in connect
    self._conn = self.get_connection()
  File "/home/ubuntu/frappe-bench/apps/frappe/frappe/database/mariadb/database.py", line 98, in get_connection
    conn = self._get_connection()
  File "/home/ubuntu/frappe-bench/apps/frappe/frappe/database/mariadb/database.py", line 104, in _get_connection
    return self.create_connection()
  File "/home/ubuntu/frappe-bench/apps/frappe/frappe/database/mariadb/database.py", line 107, in create_connection
    return pymysql.connect(**self.get_connection_settings())
  File "/home/ubuntu/frappe-bench/env/lib/python3.10/site-packages/pymysql/connections.py", line 352, in __init__
    self.connect()
  File "/home/ubuntu/frappe-bench/env/lib/python3.10/site-packages/pymysql/connections.py", line 636, in connect
    self._request_authentication()
  File "/home/ubuntu/frappe-bench/env/lib/python3.10/site-packages/pymysql/connections.py", line 911, in _request_authentication
    auth_packet = self._read_packet()
  File "/home/ubuntu/frappe-bench/env/lib/python3.10/site-packages/pymysql/connections.py", line 729, in _read_packet
    packet.raise_for_error()
  File "/home/ubuntu/frappe-bench/env/lib/python3.10/site-packages/pymysql/protocol.py", line 221, in raise_for_error
    err.raise_mysql_exception(self._data)
  File "/home/ubuntu/frappe-bench/env/lib/python3.10/site-packages/pymysql/err.py", line 143, in raise_mysql_exception
    raise errorclass(errno, errval)
pymysql.err.OperationalError: (1045, "Access denied for user '_c91b619255899dde'@'localhost' (using password: YES)")

During handling of the above exception, another exception occurred:

Traceback (most recent call last):
  File "/home/ubuntu/frappe-bench/apps/frappe/frappe/utils/caching.py", line 55, in wrapper
    return frappe.local.request_cache[func][args_key]
KeyError: 5740354900026072187

During handling of the above exception, another exception occurred:

Traceback (most recent call last):
  File "/home/ubuntu/frappe-bench/apps/frappe/frappe/utils/caching.py", line 55, in wrapper
    return frappe.local.request_cache[func][args_key]
KeyError: 5485817916924960299

During handling of the above exception, another exception occurred:

Traceback (most recent call last):
  File "/home/ubuntu/frappe-bench/apps/frappe/frappe/website/serve.py", line 17, in get_response
    endpoint, renderer_instance = path_resolver.resolve()
  File "/home/ubuntu/frappe-bench/apps/frappe/frappe/website/path_resolver.py", line 36, in resolve
    resolve_redirect(self.path, request.query_string)
  File "/home/ubuntu/frappe-bench/apps/frappe/frappe/website/path_resolver.py", line 107, in resolve_redirect
    redirects = frappe.get_hooks("website_redirects")
  File "/home/ubuntu/frappe-bench/apps/frappe/frappe/__init__.py", line 1519, in get_hooks
    hooks = _dict(cache().get_value("app_hooks", _load_app_hooks))
  File "/home/ubuntu/frappe-bench/apps/frappe/frappe/utils/redis_wrapper.py", line 81, in get_value
    val = generator()
  File "/home/ubuntu/frappe-bench/apps/frappe/frappe/utils/caching.py", line 57, in wrapper
    return_val = func(*args, **kwargs)
  File "/home/ubuntu/frappe-bench/apps/frappe/frappe/__init__.py", line 1482, in _load_app_hooks
    apps = [app_name] if app_name else get_installed_apps(_ensure_on_bench=True)
  File "/home/ubuntu/frappe-bench/apps/frappe/frappe/utils/caching.py", line 57, in wrapper
    return_val = func(*args, **kwargs)
  File "/home/ubuntu/frappe-bench/apps/frappe/frappe/__init__.py", line 1438, in get_installed_apps
    installed = json.loads(db.get_global("installed_apps") or "[]")
  File "/home/ubuntu/frappe-bench/apps/frappe/frappe/database/database.py", line 975, in get_global
    return self.get_default(key, user)
  File "/home/ubuntu/frappe-bench/apps/frappe/frappe/database/database.py", line 979, in get_default
    d = self.get_defaults(key, parent)
  File "/home/ubuntu/frappe-bench/apps/frappe/frappe/database/database.py", line 995, in get_defaults
    defaults = frappe.defaults.get_defaults_for(parent)
  File "/home/ubuntu/frappe-bench/apps/frappe/frappe/defaults.py", line 238, in get_defaults_for
    frappe.qb.from_(table)
  File "/home/ubuntu/frappe-bench/apps/frappe/frappe/query_builder/utils.py", line 87, in execute_query
    result = frappe.db.sql(query, params, *args, **kwargs)  # nosemgrep
  File "/home/ubuntu/frappe-bench/apps/frappe/frappe/database/database.py", line 201, in sql
    self.connect()
  File "/home/ubuntu/frappe-bench/apps/frappe/frappe/database/database.py", line 115, in connect
    self._conn = self.get_connection()
  File "/home/ubuntu/frappe-bench/apps/frappe/frappe/database/mariadb/database.py", line 98, in get_connection
    conn = self._get_connection()
  File "/home/ubuntu/frappe-bench/apps/frappe/frappe/database/mariadb/database.py", line 104, in _get_connection
    return self.create_connection()
  File "/home/ubuntu/frappe-bench/apps/frappe/frappe/database/mariadb/database.py", line 107, in create_connection
    return pymysql.connect(**self.get_connection_settings())
  File "/home/ubuntu/frappe-bench/env/lib/python3.10/site-packages/pymysql/connections.py", line 352, in __init__
    self.connect()
  File "/home/ubuntu/frappe-bench/env/lib/python3.10/site-packages/pymysql/connections.py", line 636, in connect
    self._request_authentication()
  File "/home/ubuntu/frappe-bench/env/lib/python3.10/site-packages/pymysql/connections.py", line 911, in _request_authentication
    auth_packet = self._read_packet()
  File "/home/ubuntu/frappe-bench/env/lib/python3.10/site-packages/pymysql/connections.py", line 729, in _read_packet
    packet.raise_for_error()
  File "/home/ubuntu/frappe-bench/env/lib/python3.10/site-packages/pymysql/protocol.py", line 221, in raise_for_error
    err.raise_mysql_exception(self._data)
  File "/home/ubuntu/frappe-bench/env/lib/python3.10/site-packages/pymysql/err.py", line 143, in raise_mysql_exception
    raise errorclass(errno, errval)
pymysql.err.OperationalError: (1045, "Access denied for user '_c91b619255899dde'@'localhost' (using password: YES)")

During handling of the above exception, another exception occurred:

Traceback (most recent call last):
  File "/home/ubuntu/frappe-bench/apps/frappe/frappe/utils/caching.py", line 55, in wrapper
    return frappe.local.request_cache[func][args_key]
KeyError: 5632239266019596807

During handling of the above exception, another exception occurred:

Traceback (most recent call last):
  File "/home/ubuntu/frappe-bench/apps/frappe/frappe/app.py", line 113, in application
    response = handle_exception(e)
  File "/home/ubuntu/frappe-bench/apps/frappe/frappe/app.py", line 369, in handle_exception
    response = get_response("message", http_status_code=http_status_code)
  File "/home/ubuntu/frappe-bench/apps/frappe/frappe/website/serve.py", line 26, in get_response
    response = ErrorPage(exception=e).render()
  File "/home/ubuntu/frappe-bench/apps/frappe/frappe/website/page_renderers/error_page.py", line 7, in __init__
    super().__init__(path=path, http_status_code=http_status_code)
  File "/home/ubuntu/frappe-bench/apps/frappe/frappe/website/page_renderers/template_page.py", line 45, in __init__
    self.set_template_path()
  File "/home/ubuntu/frappe-bench/apps/frappe/frappe/website/page_renderers/template_page.py", line 53, in set_template_path
    for app in frappe.get_installed_apps(frappe_last=True):
  File "/home/ubuntu/frappe-bench/apps/frappe/frappe/utils/caching.py", line 57, in wrapper
    return_val = func(*args, **kwargs)
  File "/home/ubuntu/frappe-bench/apps/frappe/frappe/__init__.py", line 1438, in get_installed_apps
    installed = json.loads(db.get_global("installed_apps") or "[]")
  File "/home/ubuntu/frappe-bench/apps/frappe/frappe/database/database.py", line 975, in get_global
    return self.get_default(key, user)
  File "/home/ubuntu/frappe-bench/apps/frappe/frappe/database/database.py", line 979, in get_default
    d = self.get_defaults(key, parent)
  File "/home/ubuntu/frappe-bench/apps/frappe/frappe/database/database.py", line 995, in get_defaults
    defaults = frappe.defaults.get_defaults_for(parent)
  File "/home/ubuntu/frappe-bench/apps/frappe/frappe/defaults.py", line 238, in get_defaults_for
    frappe.qb.from_(table)
  File "/home/ubuntu/frappe-bench/apps/frappe/frappe/query_builder/utils.py", line 87, in execute_query
    result = frappe.db.sql(query, params, *args, **kwargs)  # nosemgrep
  File "/home/ubuntu/frappe-bench/apps/frappe/frappe/database/database.py", line 201, in sql
    self.connect()
  File "/home/ubuntu/frappe-bench/apps/frappe/frappe/database/database.py", line 115, in connect
    self._conn = self.get_connection()
  File "/home/ubuntu/frappe-bench/apps/frappe/frappe/database/mariadb/database.py", line 98, in get_connection
    conn = self._get_connection()
  File "/home/ubuntu/frappe-bench/apps/frappe/frappe/database/mariadb/database.py", line 104, in _get_connection
    return self.create_connection()
  File "/home/ubuntu/frappe-bench/apps/frappe/frappe/database/mariadb/database.py", line 107, in create_connection
    return pymysql.connect(**self.get_connection_settings())
  File "/home/ubuntu/frappe-bench/env/lib/python3.10/site-packages/pymysql/connections.py", line 352, in __init__
    self.connect()
  File "/home/ubuntu/frappe-bench/env/lib/python3.10/site-packages/pymysql/connections.py", line 636, in connect
    self._request_authentication()
  File "/home/ubuntu/frappe-bench/env/lib/python3.10/site-packages/pymysql/connections.py", line 911, in _request_authentication
    auth_packet = self._read_packet()
  File "/home/ubuntu/frappe-bench/env/lib/python3.10/site-packages/pymysql/connections.py", line 729, in _read_packet
    packet.raise_for_error()
  File "/home/ubuntu/frappe-bench/env/lib/python3.10/site-packages/pymysql/protocol.py", line 221, in raise_for_error
    err.raise_mysql_exception(self._data)
  File "/home/ubuntu/frappe-bench/env/lib/python3.10/site-packages/pymysql/err.py", line 143, in raise_mysql_exception
    raise errorclass(errno, errval)
pymysql.err.OperationalError: (1045, "Access denied for user '_c91b619255899dde'@'localhost' (using password: YES)")

During handling of the above exception, another exception occurred:

Traceback (most recent call last):
  File "/home/ubuntu/frappe-bench/apps/frappe/frappe/utils/caching.py", line 55, in wrapper
    return frappe.local.request_cache[func][args_key]
KeyError: 5740354900026072187

During handling of the above exception, another exception occurred:

Traceback (most recent call last):
  File "/home/ubuntu/frappe-bench/apps/frappe/frappe/utils/caching.py", line 55, in wrapper
    return frappe.local.request_cache[func][args_key]
KeyError: 5485817916924960299

During handling of the above exception, another exception occurred:

Traceback (most recent call last):
  File "/home/ubuntu/frappe-bench/apps/frappe/frappe/app.py", line 127, in application
    run_after_request_hooks(request, response)
  File "/home/ubuntu/frappe-bench/apps/frappe/frappe/app.py", line 143, in run_after_request_hooks
    for after_request_task in frappe.get_hooks("after_request"):
  File "/home/ubuntu/frappe-bench/apps/frappe/frappe/__init__.py", line 1519, in get_hooks
    hooks = _dict(cache().get_value("app_hooks", _load_app_hooks))
  File "/home/ubuntu/frappe-bench/apps/frappe/frappe/utils/redis_wrapper.py", line 81, in get_value
    val = generator()
  File "/home/ubuntu/frappe-bench/apps/frappe/frappe/utils/caching.py", line 57, in wrapper
    return_val = func(*args, **kwargs)
  File "/home/ubuntu/frappe-bench/apps/frappe/frappe/__init__.py", line 1482, in _load_app_hooks
    apps = [app_name] if app_name else get_installed_apps(_ensure_on_bench=True)
  File "/home/ubuntu/frappe-bench/apps/frappe/frappe/utils/caching.py", line 57, in wrapper
    return_val = func(*args, **kwargs)
  File "/home/ubuntu/frappe-bench/apps/frappe/frappe/__init__.py", line 1438, in get_installed_apps
    installed = json.loads(db.get_global("installed_apps") or "[]")
  File "/home/ubuntu/frappe-bench/apps/frappe/frappe/database/database.py", line 975, in get_global
    return self.get_default(key, user)
  File "/home/ubuntu/frappe-bench/apps/frappe/frappe/database/database.py", line 979, in get_default
    d = self.get_defaults(key, parent)
  File "/home/ubuntu/frappe-bench/apps/frappe/frappe/database/database.py", line 995, in get_defaults
    defaults = frappe.defaults.get_defaults_for(parent)
  File "/home/ubuntu/frappe-bench/apps/frappe/frappe/defaults.py", line 238, in get_defaults_for
    frappe.qb.from_(table)
  File "/home/ubuntu/frappe-bench/apps/frappe/frappe/query_builder/utils.py", line 87, in execute_query
    result = frappe.db.sql(query, params, *args, **kwargs)  # nosemgrep
  File "/home/ubuntu/frappe-bench/apps/frappe/frappe/database/database.py", line 201, in sql
    self.connect()
  File "/home/ubuntu/frappe-bench/apps/frappe/frappe/database/database.py", line 115, in connect
    self._conn = self.get_connection()
  File "/home/ubuntu/frappe-bench/apps/frappe/frappe/database/mariadb/database.py", line 98, in get_connection
    conn = self._get_connection()
  File "/home/ubuntu/frappe-bench/apps/frappe/frappe/database/mariadb/database.py", line 104, in _get_connection
    return self.create_connection()
  File "/home/ubuntu/frappe-bench/apps/frappe/frappe/database/mariadb/database.py", line 107, in create_connection
    return pymysql.connect(**self.get_connection_settings())
  File "/home/ubuntu/frappe-bench/env/lib/python3.10/site-packages/pymysql/connections.py", line 352, in __init__
    self.connect()
  File "/home/ubuntu/frappe-bench/env/lib/python3.10/site-packages/pymysql/connections.py", line 636, in connect
    self._request_authentication()
  File "/home/ubuntu/frappe-bench/env/lib/python3.10/site-packages/pymysql/connections.py", line 911, in _request_authentication
    auth_packet = self._read_packet()
  File "/home/ubuntu/frappe-bench/env/lib/python3.10/site-packages/pymysql/connections.py", line 729, in _read_packet
    packet.raise_for_error()
  File "/home/ubuntu/frappe-bench/env/lib/python3.10/site-packages/pymysql/protocol.py", line 221, in raise_for_error
    err.raise_mysql_exception(self._data)
  File "/home/ubuntu/frappe-bench/env/lib/python3.10/site-packages/pymysql/err.py", line 143, in raise_mysql_exception
    raise errorclass(errno, errval)
pymysql.err.OperationalError: (1045, "Access denied for user '_c91b619255899dde'@'localhost' (using password: YES)")
2023-12-20 18:45:04,080 ERROR frappe New Exception collected with id: 2023-12-20 18:45:03.888375-127.0.0.1-74f
Site: site2.local
Form Dict: {}
2023-12-20 18:45:04,089 ERROR frappe Failed to run after request hook
Site: site2.local
Form Dict: {}
Traceback (most recent call last):
  File "/home/ubuntu/frappe-bench/apps/frappe/frappe/app.py", line 84, in application
    init_request(request)
  File "/home/ubuntu/frappe-bench/apps/frappe/frappe/app.py", line 175, in init_request
    frappe.local.http_request = frappe.auth.HTTPRequest()
  File "/home/ubuntu/frappe-bench/apps/frappe/frappe/auth.py", line 37, in __init__
    self.set_session()
  File "/home/ubuntu/frappe-bench/apps/frappe/frappe/auth.py", line 73, in set_session
    frappe.local.login_manager = LoginManager()
  File "/home/ubuntu/frappe-bench/apps/frappe/frappe/auth.py", line 122, in __init__
    self.make_session(resume=True)
  File "/home/ubuntu/frappe-bench/apps/frappe/frappe/auth.py", line 210, in make_session
    frappe.local.session_obj = Session(
  File "/home/ubuntu/frappe-bench/apps/frappe/frappe/sessions.py", line 230, in __init__
    self.resume()
  File "/home/ubuntu/frappe-bench/apps/frappe/frappe/sessions.py", line 303, in resume
    data = self.get_session_record()
  File "/home/ubuntu/frappe-bench/apps/frappe/frappe/sessions.py", line 321, in get_session_record
    r = self.get_session_data()
  File "/home/ubuntu/frappe-bench/apps/frappe/frappe/sessions.py", line 337, in get_session_data
    data = self.get_session_data_from_db()
  File "/home/ubuntu/frappe-bench/apps/frappe/frappe/sessions.py", line 362, in get_session_data_from_db
    frappe.db.get_value(
  File "/home/ubuntu/frappe-bench/apps/frappe/frappe/database/database.py", line 509, in get_value
    result = self.get_values(
  File "/home/ubuntu/frappe-bench/apps/frappe/frappe/database/database.py", line 606, in get_values
    out = self._get_values_from_table(
  File "/home/ubuntu/frappe-bench/apps/frappe/frappe/database/database.py", line 835, in _get_values_from_table
    return query.run(as_dict=as_dict, debug=debug, update=update, run=run, pluck=pluck)
  File "/home/ubuntu/frappe-bench/apps/frappe/frappe/query_builder/utils.py", line 87, in execute_query
    result = frappe.db.sql(query, params, *args, **kwargs)  # nosemgrep
  File "/home/ubuntu/frappe-bench/apps/frappe/frappe/database/database.py", line 201, in sql
    self.connect()
  File "/home/ubuntu/frappe-bench/apps/frappe/frappe/database/database.py", line 115, in connect
    self._conn = self.get_connection()
  File "/home/ubuntu/frappe-bench/apps/frappe/frappe/database/mariadb/database.py", line 98, in get_connection
    conn = self._get_connection()
  File "/home/ubuntu/frappe-bench/apps/frappe/frappe/database/mariadb/database.py", line 104, in _get_connection
    return self.create_connection()
  File "/home/ubuntu/frappe-bench/apps/frappe/frappe/database/mariadb/database.py", line 107, in create_connection
    return pymysql.connect(**self.get_connection_settings())
  File "/home/ubuntu/frappe-bench/env/lib/python3.10/site-packages/pymysql/connections.py", line 352, in __init__
    self.connect()
  File "/home/ubuntu/frappe-bench/env/lib/python3.10/site-packages/pymysql/connections.py", line 636, in connect
    self._request_authentication()
  File "/home/ubuntu/frappe-bench/env/lib/python3.10/site-packages/pymysql/connections.py", line 911, in _request_authentication
    auth_packet = self._read_packet()
  File "/home/ubuntu/frappe-bench/env/lib/python3.10/site-packages/pymysql/connections.py", line 729, in _read_packet
    packet.raise_for_error()
  File "/home/ubuntu/frappe-bench/env/lib/python3.10/site-packages/pymysql/protocol.py", line 221, in raise_for_error
    err.raise_mysql_exception(self._data)
  File "/home/ubuntu/frappe-bench/env/lib/python3.10/site-packages/pymysql/err.py", line 143, in raise_mysql_exception
    raise errorclass(errno, errval)
pymysql.err.OperationalError: (1045, "Access denied for user '_c91b619255899dde'@'localhost' (using password: YES)")

During handling of the above exception, another exception occurred:

Traceback (most recent call last):
  File "/home/ubuntu/frappe-bench/apps/frappe/frappe/utils/caching.py", line 55, in wrapper
    return frappe.local.request_cache[func][args_key]
KeyError: 5740354900026072187

During handling of the above exception, another exception occurred:

Traceback (most recent call last):
  File "/home/ubuntu/frappe-bench/apps/frappe/frappe/utils/caching.py", line 55, in wrapper
    return frappe.local.request_cache[func][args_key]
KeyError: 2052733067153067481

During handling of the above exception, another exception occurred:

Traceback (most recent call last):
  File "/home/ubuntu/frappe-bench/apps/frappe/frappe/website/serve.py", line 17, in get_response
    endpoint, renderer_instance = path_resolver.resolve()
  File "/home/ubuntu/frappe-bench/apps/frappe/frappe/website/path_resolver.py", line 36, in resolve
    resolve_redirect(self.path, request.query_string)
  File "/home/ubuntu/frappe-bench/apps/frappe/frappe/website/path_resolver.py", line 107, in resolve_redirect
    redirects = frappe.get_hooks("website_redirects")
  File "/home/ubuntu/frappe-bench/apps/frappe/frappe/__init__.py", line 1519, in get_hooks
    hooks = _dict(cache().get_value("app_hooks", _load_app_hooks))
  File "/home/ubuntu/frappe-bench/apps/frappe/frappe/utils/redis_wrapper.py", line 81, in get_value
    val = generator()
  File "/home/ubuntu/frappe-bench/apps/frappe/frappe/utils/caching.py", line 57, in wrapper
    return_val = func(*args, **kwargs)
  File "/home/ubuntu/frappe-bench/apps/frappe/frappe/__init__.py", line 1482, in _load_app_hooks
    apps = [app_name] if app_name else get_installed_apps(_ensure_on_bench=True)
  File "/home/ubuntu/frappe-bench/apps/frappe/frappe/utils/caching.py", line 57, in wrapper
    return_val = func(*args, **kwargs)
  File "/home/ubuntu/frappe-bench/apps/frappe/frappe/__init__.py", line 1438, in get_installed_apps
    installed = json.loads(db.get_global("installed_apps") or "[]")
  File "/home/ubuntu/frappe-bench/apps/frappe/frappe/database/database.py", line 975, in get_global
    return self.get_default(key, user)
  File "/home/ubuntu/frappe-bench/apps/frappe/frappe/database/database.py", line 979, in get_default
    d = self.get_defaults(key, parent)
  File "/home/ubuntu/frappe-bench/apps/frappe/frappe/database/database.py", line 995, in get_defaults
    defaults = frappe.defaults.get_defaults_for(parent)
  File "/home/ubuntu/frappe-bench/apps/frappe/frappe/defaults.py", line 238, in get_defaults_for
    frappe.qb.from_(table)
  File "/home/ubuntu/frappe-bench/apps/frappe/frappe/query_builder/utils.py", line 87, in execute_query
    result = frappe.db.sql(query, params, *args, **kwargs)  # nosemgrep
  File "/home/ubuntu/frappe-bench/apps/frappe/frappe/database/database.py", line 201, in sql
    self.connect()
  File "/home/ubuntu/frappe-bench/apps/frappe/frappe/database/database.py", line 115, in connect
    self._conn = self.get_connection()
  File "/home/ubuntu/frappe-bench/apps/frappe/frappe/database/mariadb/database.py", line 98, in get_connection
    conn = self._get_connection()
  File "/home/ubuntu/frappe-bench/apps/frappe/frappe/database/mariadb/database.py", line 104, in _get_connection
    return self.create_connection()
  File "/home/ubuntu/frappe-bench/apps/frappe/frappe/database/mariadb/database.py", line 107, in create_connection
    return pymysql.connect(**self.get_connection_settings())
  File "/home/ubuntu/frappe-bench/env/lib/python3.10/site-packages/pymysql/connections.py", line 352, in __init__
    self.connect()
  File "/home/ubuntu/frappe-bench/env/lib/python3.10/site-packages/pymysql/connections.py", line 636, in connect
    self._request_authentication()
  File "/home/ubuntu/frappe-bench/env/lib/python3.10/site-packages/pymysql/connections.py", line 911, in _request_authentication
    auth_packet = self._read_packet()
  File "/home/ubuntu/frappe-bench/env/lib/python3.10/site-packages/pymysql/connections.py", line 729, in _read_packet
    packet.raise_for_error()
  File "/home/ubuntu/frappe-bench/env/lib/python3.10/site-packages/pymysql/protocol.py", line 221, in raise_for_error
    err.raise_mysql_exception(self._data)
  File "/home/ubuntu/frappe-bench/env/lib/python3.10/site-packages/pymysql/err.py", line 143, in raise_mysql_exception
    raise errorclass(errno, errval)
pymysql.err.OperationalError: (1045, "Access denied for user '_c91b619255899dde'@'localhost' (using password: YES)")

During handling of the above exception, another exception occurred:

Traceback (most recent call last):
  File "/home/ubuntu/frappe-bench/apps/frappe/frappe/utils/caching.py", line 55, in wrapper
    return frappe.local.request_cache[func][args_key]
KeyError: -1168096087100648513

During handling of the above exception, another exception occurred:

Traceback (most recent call last):
  File "/home/ubuntu/frappe-bench/apps/frappe/frappe/app.py", line 113, in application
    response = handle_exception(e)
  File "/home/ubuntu/frappe-bench/apps/frappe/frappe/app.py", line 369, in handle_exception
    response = get_response("message", http_status_code=http_status_code)
  File "/home/ubuntu/frappe-bench/apps/frappe/frappe/website/serve.py", line 26, in get_response
    response = ErrorPage(exception=e).render()
  File "/home/ubuntu/frappe-bench/apps/frappe/frappe/website/page_renderers/error_page.py", line 7, in __init__
    super().__init__(path=path, http_status_code=http_status_code)
  File "/home/ubuntu/frappe-bench/apps/frappe/frappe/website/page_renderers/template_page.py", line 45, in __init__
    self.set_template_path()
  File "/home/ubuntu/frappe-bench/apps/frappe/frappe/website/page_renderers/template_page.py", line 53, in set_template_path
    for app in frappe.get_installed_apps(frappe_last=True):
  File "/home/ubuntu/frappe-bench/apps/frappe/frappe/utils/caching.py", line 57, in wrapper
    return_val = func(*args, **kwargs)
  File "/home/ubuntu/frappe-bench/apps/frappe/frappe/__init__.py", line 1438, in get_installed_apps
    installed = json.loads(db.get_global("installed_apps") or "[]")
  File "/home/ubuntu/frappe-bench/apps/frappe/frappe/database/database.py", line 975, in get_global
    return self.get_default(key, user)
  File "/home/ubuntu/frappe-bench/apps/frappe/frappe/database/database.py", line 979, in get_default
    d = self.get_defaults(key, parent)
  File "/home/ubuntu/frappe-bench/apps/frappe/frappe/database/database.py", line 995, in get_defaults
    defaults = frappe.defaults.get_defaults_for(parent)
  File "/home/ubuntu/frappe-bench/apps/frappe/frappe/defaults.py", line 238, in get_defaults_for
    frappe.qb.from_(table)
  File "/home/ubuntu/frappe-bench/apps/frappe/frappe/query_builder/utils.py", line 87, in execute_query
    result = frappe.db.sql(query, params, *args, **kwargs)  # nosemgrep
  File "/home/ubuntu/frappe-bench/apps/frappe/frappe/database/database.py", line 201, in sql
    self.connect()
  File "/home/ubuntu/frappe-bench/apps/frappe/frappe/database/database.py", line 115, in connect
    self._conn = self.get_connection()
  File "/home/ubuntu/frappe-bench/apps/frappe/frappe/database/mariadb/database.py", line 98, in get_connection
    conn = self._get_connection()
  File "/home/ubuntu/frappe-bench/apps/frappe/frappe/database/mariadb/database.py", line 104, in _get_connection
    return self.create_connection()
  File "/home/ubuntu/frappe-bench/apps/frappe/frappe/database/mariadb/database.py", line 107, in create_connection
    return pymysql.connect(**self.get_connection_settings())
  File "/home/ubuntu/frappe-bench/env/lib/python3.10/site-packages/pymysql/connections.py", line 352, in __init__
    self.connect()
  File "/home/ubuntu/frappe-bench/env/lib/python3.10/site-packages/pymysql/connections.py", line 636, in connect
    self._request_authentication()
  File "/home/ubuntu/frappe-bench/env/lib/python3.10/site-packages/pymysql/connections.py", line 911, in _request_authentication
    auth_packet = self._read_packet()
  File "/home/ubuntu/frappe-bench/env/lib/python3.10/site-packages/pymysql/connections.py", line 729, in _read_packet
    packet.raise_for_error()
  File "/home/ubuntu/frappe-bench/env/lib/python3.10/site-packages/pymysql/protocol.py", line 221, in raise_for_error
    err.raise_mysql_exception(self._data)
  File "/home/ubuntu/frappe-bench/env/lib/python3.10/site-packages/pymysql/err.py", line 143, in raise_mysql_exception
    raise errorclass(errno, errval)
pymysql.err.OperationalError: (1045, "Access denied for user '_c91b619255899dde'@'localhost' (using password: YES)")

During handling of the above exception, another exception occurred:

Traceback (most recent call last):
  File "/home/ubuntu/frappe-bench/apps/frappe/frappe/utils/caching.py", line 55, in wrapper
    return frappe.local.request_cache[func][args_key]
KeyError: 5740354900026072187

During handling of the above exception, another exception occurred:

Traceback (most recent call last):
  File "/home/ubuntu/frappe-bench/apps/frappe/frappe/utils/caching.py", line 55, in wrapper
    return frappe.local.request_cache[func][args_key]
KeyError: 2052733067153067481

During handling of the above exception, another exception occurred:

Traceback (most recent call last):
  File "/home/ubuntu/frappe-bench/apps/frappe/frappe/app.py", line 127, in application
    run_after_request_hooks(request, response)
  File "/home/ubuntu/frappe-bench/apps/frappe/frappe/app.py", line 143, in run_after_request_hooks
    for after_request_task in frappe.get_hooks("after_request"):
  File "/home/ubuntu/frappe-bench/apps/frappe/frappe/__init__.py", line 1519, in get_hooks
    hooks = _dict(cache().get_value("app_hooks", _load_app_hooks))
  File "/home/ubuntu/frappe-bench/apps/frappe/frappe/utils/redis_wrapper.py", line 81, in get_value
    val = generator()
  File "/home/ubuntu/frappe-bench/apps/frappe/frappe/utils/caching.py", line 57, in wrapper
    return_val = func(*args, **kwargs)
  File "/home/ubuntu/frappe-bench/apps/frappe/frappe/__init__.py", line 1482, in _load_app_hooks
    apps = [app_name] if app_name else get_installed_apps(_ensure_on_bench=True)
  File "/home/ubuntu/frappe-bench/apps/frappe/frappe/utils/caching.py", line 57, in wrapper
    return_val = func(*args, **kwargs)
  File "/home/ubuntu/frappe-bench/apps/frappe/frappe/__init__.py", line 1438, in get_installed_apps
    installed = json.loads(db.get_global("installed_apps") or "[]")
  File "/home/ubuntu/frappe-bench/apps/frappe/frappe/database/database.py", line 975, in get_global
    return self.get_default(key, user)
  File "/home/ubuntu/frappe-bench/apps/frappe/frappe/database/database.py", line 979, in get_default
    d = self.get_defaults(key, parent)
  File "/home/ubuntu/frappe-bench/apps/frappe/frappe/database/database.py", line 995, in get_defaults
    defaults = frappe.defaults.get_defaults_for(parent)
  File "/home/ubuntu/frappe-bench/apps/frappe/frappe/defaults.py", line 238, in get_defaults_for
    frappe.qb.from_(table)
  File "/home/ubuntu/frappe-bench/apps/frappe/frappe/query_builder/utils.py", line 87, in execute_query
    result = frappe.db.sql(query, params, *args, **kwargs)  # nosemgrep
  File "/home/ubuntu/frappe-bench/apps/frappe/frappe/database/database.py", line 201, in sql
    self.connect()
  File "/home/ubuntu/frappe-bench/apps/frappe/frappe/database/database.py", line 115, in connect
    self._conn = self.get_connection()
  File "/home/ubuntu/frappe-bench/apps/frappe/frappe/database/mariadb/database.py", line 98, in get_connection
    conn = self._get_connection()
  File "/home/ubuntu/frappe-bench/apps/frappe/frappe/database/mariadb/database.py", line 104, in _get_connection
    return self.create_connection()
  File "/home/ubuntu/frappe-bench/apps/frappe/frappe/database/mariadb/database.py", line 107, in create_connection
    return pymysql.connect(**self.get_connection_settings())
  File "/home/ubuntu/frappe-bench/env/lib/python3.10/site-packages/pymysql/connections.py", line 352, in __init__
    self.connect()
  File "/home/ubuntu/frappe-bench/env/lib/python3.10/site-packages/pymysql/connections.py", line 636, in connect
    self._request_authentication()
  File "/home/ubuntu/frappe-bench/env/lib/python3.10/site-packages/pymysql/connections.py", line 911, in _request_authentication
    auth_packet = self._read_packet()
  File "/home/ubuntu/frappe-bench/env/lib/python3.10/site-packages/pymysql/connections.py", line 729, in _read_packet
    packet.raise_for_error()
  File "/home/ubuntu/frappe-bench/env/lib/python3.10/site-packages/pymysql/protocol.py", line 221, in raise_for_error
    err.raise_mysql_exception(self._data)
  File "/home/ubuntu/frappe-bench/env/lib/python3.10/site-packages/pymysql/err.py", line 143, in raise_mysql_exception
    raise errorclass(errno, errval)
pymysql.err.OperationalError: (1045, "Access denied for user '_c91b619255899dde'@'localhost' (using password: YES)")
2023-12-20 18:48:25,928 ERROR frappe New Exception collected with id: 2023-12-20 18:48:25.679035-127.0.0.1-c49
Site: site2.local
Form Dict: {}
2023-12-20 18:48:25,940 ERROR frappe Failed to run after request hook
Site: site2.local
Form Dict: {}
Traceback (most recent call last):
  File "/home/ubuntu/frappe-bench/apps/frappe/frappe/app.py", line 84, in application
    init_request(request)
  File "/home/ubuntu/frappe-bench/apps/frappe/frappe/app.py", line 175, in init_request
    frappe.local.http_request = frappe.auth.HTTPRequest()
  File "/home/ubuntu/frappe-bench/apps/frappe/frappe/auth.py", line 37, in __init__
    self.set_session()
  File "/home/ubuntu/frappe-bench/apps/frappe/frappe/auth.py", line 73, in set_session
    frappe.local.login_manager = LoginManager()
  File "/home/ubuntu/frappe-bench/apps/frappe/frappe/auth.py", line 122, in __init__
    self.make_session(resume=True)
  File "/home/ubuntu/frappe-bench/apps/frappe/frappe/auth.py", line 210, in make_session
    frappe.local.session_obj = Session(
  File "/home/ubuntu/frappe-bench/apps/frappe/frappe/sessions.py", line 230, in __init__
    self.resume()
  File "/home/ubuntu/frappe-bench/apps/frappe/frappe/sessions.py", line 303, in resume
    data = self.get_session_record()
  File "/home/ubuntu/frappe-bench/apps/frappe/frappe/sessions.py", line 321, in get_session_record
    r = self.get_session_data()
  File "/home/ubuntu/frappe-bench/apps/frappe/frappe/sessions.py", line 337, in get_session_data
    data = self.get_session_data_from_db()
  File "/home/ubuntu/frappe-bench/apps/frappe/frappe/sessions.py", line 362, in get_session_data_from_db
    frappe.db.get_value(
  File "/home/ubuntu/frappe-bench/apps/frappe/frappe/database/database.py", line 509, in get_value
    result = self.get_values(
  File "/home/ubuntu/frappe-bench/apps/frappe/frappe/database/database.py", line 606, in get_values
    out = self._get_values_from_table(
  File "/home/ubuntu/frappe-bench/apps/frappe/frappe/database/database.py", line 835, in _get_values_from_table
    return query.run(as_dict=as_dict, debug=debug, update=update, run=run, pluck=pluck)
  File "/home/ubuntu/frappe-bench/apps/frappe/frappe/query_builder/utils.py", line 87, in execute_query
    result = frappe.db.sql(query, params, *args, **kwargs)  # nosemgrep
  File "/home/ubuntu/frappe-bench/apps/frappe/frappe/database/database.py", line 201, in sql
    self.connect()
  File "/home/ubuntu/frappe-bench/apps/frappe/frappe/database/database.py", line 115, in connect
    self._conn = self.get_connection()
  File "/home/ubuntu/frappe-bench/apps/frappe/frappe/database/mariadb/database.py", line 98, in get_connection
    conn = self._get_connection()
  File "/home/ubuntu/frappe-bench/apps/frappe/frappe/database/mariadb/database.py", line 104, in _get_connection
    return self.create_connection()
  File "/home/ubuntu/frappe-bench/apps/frappe/frappe/database/mariadb/database.py", line 107, in create_connection
    return pymysql.connect(**self.get_connection_settings())
  File "/home/ubuntu/frappe-bench/env/lib/python3.10/site-packages/pymysql/connections.py", line 352, in __init__
    self.connect()
  File "/home/ubuntu/frappe-bench/env/lib/python3.10/site-packages/pymysql/connections.py", line 636, in connect
    self._request_authentication()
  File "/home/ubuntu/frappe-bench/env/lib/python3.10/site-packages/pymysql/connections.py", line 911, in _request_authentication
    auth_packet = self._read_packet()
  File "/home/ubuntu/frappe-bench/env/lib/python3.10/site-packages/pymysql/connections.py", line 729, in _read_packet
    packet.raise_for_error()
  File "/home/ubuntu/frappe-bench/env/lib/python3.10/site-packages/pymysql/protocol.py", line 221, in raise_for_error
    err.raise_mysql_exception(self._data)
  File "/home/ubuntu/frappe-bench/env/lib/python3.10/site-packages/pymysql/err.py", line 143, in raise_mysql_exception
    raise errorclass(errno, errval)
pymysql.err.OperationalError: (1045, "Access denied for user '_c91b619255899dde'@'localhost' (using password: YES)")

During handling of the above exception, another exception occurred:

Traceback (most recent call last):
  File "/home/ubuntu/frappe-bench/apps/frappe/frappe/utils/caching.py", line 55, in wrapper
    return frappe.local.request_cache[func][args_key]
KeyError: 5740354900026072187

During handling of the above exception, another exception occurred:

Traceback (most recent call last):
  File "/home/ubuntu/frappe-bench/apps/frappe/frappe/utils/caching.py", line 55, in wrapper
    return frappe.local.request_cache[func][args_key]
KeyError: 7656477958881702411

During handling of the above exception, another exception occurred:

Traceback (most recent call last):
  File "/home/ubuntu/frappe-bench/apps/frappe/frappe/website/serve.py", line 17, in get_response
    endpoint, renderer_instance = path_resolver.resolve()
  File "/home/ubuntu/frappe-bench/apps/frappe/frappe/website/path_resolver.py", line 36, in resolve
    resolve_redirect(self.path, request.query_string)
  File "/home/ubuntu/frappe-bench/apps/frappe/frappe/website/path_resolver.py", line 107, in resolve_redirect
    redirects = frappe.get_hooks("website_redirects")
  File "/home/ubuntu/frappe-bench/apps/frappe/frappe/__init__.py", line 1519, in get_hooks
    hooks = _dict(cache().get_value("app_hooks", _load_app_hooks))
  File "/home/ubuntu/frappe-bench/apps/frappe/frappe/utils/redis_wrapper.py", line 81, in get_value
    val = generator()
  File "/home/ubuntu/frappe-bench/apps/frappe/frappe/utils/caching.py", line 57, in wrapper
    return_val = func(*args, **kwargs)
  File "/home/ubuntu/frappe-bench/apps/frappe/frappe/__init__.py", line 1482, in _load_app_hooks
    apps = [app_name] if app_name else get_installed_apps(_ensure_on_bench=True)
  File "/home/ubuntu/frappe-bench/apps/frappe/frappe/utils/caching.py", line 57, in wrapper
    return_val = func(*args, **kwargs)
  File "/home/ubuntu/frappe-bench/apps/frappe/frappe/__init__.py", line 1438, in get_installed_apps
    installed = json.loads(db.get_global("installed_apps") or "[]")
  File "/home/ubuntu/frappe-bench/apps/frappe/frappe/database/database.py", line 975, in get_global
    return self.get_default(key, user)
  File "/home/ubuntu/frappe-bench/apps/frappe/frappe/database/database.py", line 979, in get_default
    d = self.get_defaults(key, parent)
  File "/home/ubuntu/frappe-bench/apps/frappe/frappe/database/database.py", line 995, in get_defaults
    defaults = frappe.defaults.get_defaults_for(parent)
  File "/home/ubuntu/frappe-bench/apps/frappe/frappe/defaults.py", line 238, in get_defaults_for
    frappe.qb.from_(table)
  File "/home/ubuntu/frappe-bench/apps/frappe/frappe/query_builder/utils.py", line 87, in execute_query
    result = frappe.db.sql(query, params, *args, **kwargs)  # nosemgrep
  File "/home/ubuntu/frappe-bench/apps/frappe/frappe/database/database.py", line 201, in sql
    self.connect()
  File "/home/ubuntu/frappe-bench/apps/frappe/frappe/database/database.py", line 115, in connect
    self._conn = self.get_connection()
  File "/home/ubuntu/frappe-bench/apps/frappe/frappe/database/mariadb/database.py", line 98, in get_connection
    conn = self._get_connection()
  File "/home/ubuntu/frappe-bench/apps/frappe/frappe/database/mariadb/database.py", line 104, in _get_connection
    return self.create_connection()
  File "/home/ubuntu/frappe-bench/apps/frappe/frappe/database/mariadb/database.py", line 107, in create_connection
    return pymysql.connect(**self.get_connection_settings())
  File "/home/ubuntu/frappe-bench/env/lib/python3.10/site-packages/pymysql/connections.py", line 352, in __init__
    self.connect()
  File "/home/ubuntu/frappe-bench/env/lib/python3.10/site-packages/pymysql/connections.py", line 636, in connect
    self._request_authentication()
  File "/home/ubuntu/frappe-bench/env/lib/python3.10/site-packages/pymysql/connections.py", line 911, in _request_authentication
    auth_packet = self._read_packet()
  File "/home/ubuntu/frappe-bench/env/lib/python3.10/site-packages/pymysql/connections.py", line 729, in _read_packet
    packet.raise_for_error()
  File "/home/ubuntu/frappe-bench/env/lib/python3.10/site-packages/pymysql/protocol.py", line 221, in raise_for_error
    err.raise_mysql_exception(self._data)
  File "/home/ubuntu/frappe-bench/env/lib/python3.10/site-packages/pymysql/err.py", line 143, in raise_mysql_exception
    raise errorclass(errno, errval)
pymysql.err.OperationalError: (1045, "Access denied for user '_c91b619255899dde'@'localhost' (using password: YES)")

During handling of the above exception, another exception occurred:

Traceback (most recent call last):
  File "/home/ubuntu/frappe-bench/apps/frappe/frappe/utils/caching.py", line 55, in wrapper
    return frappe.local.request_cache[func][args_key]
KeyError: -8421728259947807239

During handling of the above exception, another exception occurred:

Traceback (most recent call last):
  File "/home/ubuntu/frappe-bench/apps/frappe/frappe/app.py", line 113, in application
    response = handle_exception(e)
  File "/home/ubuntu/frappe-bench/apps/frappe/frappe/app.py", line 369, in handle_exception
    response = get_response("message", http_status_code=http_status_code)
  File "/home/ubuntu/frappe-bench/apps/frappe/frappe/website/serve.py", line 26, in get_response
    response = ErrorPage(exception=e).render()
  File "/home/ubuntu/frappe-bench/apps/frappe/frappe/website/page_renderers/error_page.py", line 7, in __init__
    super().__init__(path=path, http_status_code=http_status_code)
  File "/home/ubuntu/frappe-bench/apps/frappe/frappe/website/page_renderers/template_page.py", line 45, in __init__
    self.set_template_path()
  File "/home/ubuntu/frappe-bench/apps/frappe/frappe/website/page_renderers/template_page.py", line 53, in set_template_path
    for app in frappe.get_installed_apps(frappe_last=True):
  File "/home/ubuntu/frappe-bench/apps/frappe/frappe/utils/caching.py", line 57, in wrapper
    return_val = func(*args, **kwargs)
  File "/home/ubuntu/frappe-bench/apps/frappe/frappe/__init__.py", line 1438, in get_installed_apps
    installed = json.loads(db.get_global("installed_apps") or "[]")
  File "/home/ubuntu/frappe-bench/apps/frappe/frappe/database/database.py", line 975, in get_global
    return self.get_default(key, user)
  File "/home/ubuntu/frappe-bench/apps/frappe/frappe/database/database.py", line 979, in get_default
    d = self.get_defaults(key, parent)
  File "/home/ubuntu/frappe-bench/apps/frappe/frappe/database/database.py", line 995, in get_defaults
    defaults = frappe.defaults.get_defaults_for(parent)
  File "/home/ubuntu/frappe-bench/apps/frappe/frappe/defaults.py", line 238, in get_defaults_for
    frappe.qb.from_(table)
  File "/home/ubuntu/frappe-bench/apps/frappe/frappe/query_builder/utils.py", line 87, in execute_query
    result = frappe.db.sql(query, params, *args, **kwargs)  # nosemgrep
  File "/home/ubuntu/frappe-bench/apps/frappe/frappe/database/database.py", line 201, in sql
    self.connect()
  File "/home/ubuntu/frappe-bench/apps/frappe/frappe/database/database.py", line 115, in connect
    self._conn = self.get_connection()
  File "/home/ubuntu/frappe-bench/apps/frappe/frappe/database/mariadb/database.py", line 98, in get_connection
    conn = self._get_connection()
  File "/home/ubuntu/frappe-bench/apps/frappe/frappe/database/mariadb/database.py", line 104, in _get_connection
    return self.create_connection()
  File "/home/ubuntu/frappe-bench/apps/frappe/frappe/database/mariadb/database.py", line 107, in create_connection
    return pymysql.connect(**self.get_connection_settings())
  File "/home/ubuntu/frappe-bench/env/lib/python3.10/site-packages/pymysql/connections.py", line 352, in __init__
    self.connect()
  File "/home/ubuntu/frappe-bench/env/lib/python3.10/site-packages/pymysql/connections.py", line 636, in connect
    self._request_authentication()
  File "/home/ubuntu/frappe-bench/env/lib/python3.10/site-packages/pymysql/connections.py", line 911, in _request_authentication
    auth_packet = self._read_packet()
  File "/home/ubuntu/frappe-bench/env/lib/python3.10/site-packages/pymysql/connections.py", line 729, in _read_packet
    packet.raise_for_error()
  File "/home/ubuntu/frappe-bench/env/lib/python3.10/site-packages/pymysql/protocol.py", line 221, in raise_for_error
    err.raise_mysql_exception(self._data)
  File "/home/ubuntu/frappe-bench/env/lib/python3.10/site-packages/pymysql/err.py", line 143, in raise_mysql_exception
    raise errorclass(errno, errval)
pymysql.err.OperationalError: (1045, "Access denied for user '_c91b619255899dde'@'localhost' (using password: YES)")

During handling of the above exception, another exception occurred:

Traceback (most recent call last):
  File "/home/ubuntu/frappe-bench/apps/frappe/frappe/utils/caching.py", line 55, in wrapper
    return frappe.local.request_cache[func][args_key]
KeyError: 5740354900026072187

During handling of the above exception, another exception occurred:

Traceback (most recent call last):
  File "/home/ubuntu/frappe-bench/apps/frappe/frappe/utils/caching.py", line 55, in wrapper
    return frappe.local.request_cache[func][args_key]
KeyError: 7656477958881702411

During handling of the above exception, another exception occurred:

Traceback (most recent call last):
  File "/home/ubuntu/frappe-bench/apps/frappe/frappe/app.py", line 127, in application
    run_after_request_hooks(request, response)
  File "/home/ubuntu/frappe-bench/apps/frappe/frappe/app.py", line 143, in run_after_request_hooks
    for after_request_task in frappe.get_hooks("after_request"):
  File "/home/ubuntu/frappe-bench/apps/frappe/frappe/__init__.py", line 1519, in get_hooks
    hooks = _dict(cache().get_value("app_hooks", _load_app_hooks))
  File "/home/ubuntu/frappe-bench/apps/frappe/frappe/utils/redis_wrapper.py", line 81, in get_value
    val = generator()
  File "/home/ubuntu/frappe-bench/apps/frappe/frappe/utils/caching.py", line 57, in wrapper
    return_val = func(*args, **kwargs)
  File "/home/ubuntu/frappe-bench/apps/frappe/frappe/__init__.py", line 1482, in _load_app_hooks
    apps = [app_name] if app_name else get_installed_apps(_ensure_on_bench=True)
  File "/home/ubuntu/frappe-bench/apps/frappe/frappe/utils/caching.py", line 57, in wrapper
    return_val = func(*args, **kwargs)
  File "/home/ubuntu/frappe-bench/apps/frappe/frappe/__init__.py", line 1438, in get_installed_apps
    installed = json.loads(db.get_global("installed_apps") or "[]")
  File "/home/ubuntu/frappe-bench/apps/frappe/frappe/database/database.py", line 975, in get_global
    return self.get_default(key, user)
  File "/home/ubuntu/frappe-bench/apps/frappe/frappe/database/database.py", line 979, in get_default
    d = self.get_defaults(key, parent)
  File "/home/ubuntu/frappe-bench/apps/frappe/frappe/database/database.py", line 995, in get_defaults
    defaults = frappe.defaults.get_defaults_for(parent)
  File "/home/ubuntu/frappe-bench/apps/frappe/frappe/defaults.py", line 238, in get_defaults_for
    frappe.qb.from_(table)
  File "/home/ubuntu/frappe-bench/apps/frappe/frappe/query_builder/utils.py", line 87, in execute_query
    result = frappe.db.sql(query, params, *args, **kwargs)  # nosemgrep
  File "/home/ubuntu/frappe-bench/apps/frappe/frappe/database/database.py", line 201, in sql
    self.connect()
  File "/home/ubuntu/frappe-bench/apps/frappe/frappe/database/database.py", line 115, in connect
    self._conn = self.get_connection()
  File "/home/ubuntu/frappe-bench/apps/frappe/frappe/database/mariadb/database.py", line 98, in get_connection
    conn = self._get_connection()
  File "/home/ubuntu/frappe-bench/apps/frappe/frappe/database/mariadb/database.py", line 104, in _get_connection
    return self.create_connection()
  File "/home/ubuntu/frappe-bench/apps/frappe/frappe/database/mariadb/database.py", line 107, in create_connection
    return pymysql.connect(**self.get_connection_settings())
  File "/home/ubuntu/frappe-bench/env/lib/python3.10/site-packages/pymysql/connections.py", line 352, in __init__
    self.connect()
  File "/home/ubuntu/frappe-bench/env/lib/python3.10/site-packages/pymysql/connections.py", line 636, in connect
    self._request_authentication()
  File "/home/ubuntu/frappe-bench/env/lib/python3.10/site-packages/pymysql/connections.py", line 911, in _request_authentication
    auth_packet = self._read_packet()
  File "/home/ubuntu/frappe-bench/env/lib/python3.10/site-packages/pymysql/connections.py", line 729, in _read_packet
    packet.raise_for_error()
  File "/home/ubuntu/frappe-bench/env/lib/python3.10/site-packages/pymysql/protocol.py", line 221, in raise_for_error
    err.raise_mysql_exception(self._data)
  File "/home/ubuntu/frappe-bench/env/lib/python3.10/site-packages/pymysql/err.py", line 143, in raise_mysql_exception
    raise errorclass(errno, errval)
pymysql.err.OperationalError: (1045, "Access denied for user '_c91b619255899dde'@'localhost' (using password: YES)")
